Workbook

Sheet Notice
A1: NARJISS IMMOBILIERE - Grille de commercialisation
A3: Projet : Residence Al Jawhara (jawhara) - Dcheira El Jihadia, Agadir
A4: 90 lots : 3 immeubles (A, B, C) x RDC + 4 etages x 6 lots par niveau
A6: FICHIER DE DEMONSTRATION
A7: Toutes les donnees de ce fichier sont INVENTEES : surfaces, prix, statuts, arguments de
A8: vente. Elles servent a faire tourner la demonstration du parcours client de bout en bout.
A9: Elles ne doivent en aucun cas etre communiquees a un client ni servir de base a un devis.
A11: Le jour ou le bureau de vente fournira la vraie grille, il suffira de remplacer le contenu
A12: de l'onglet Lots : la structure des colonnes et l'import restent identiques.
A14: COMMENT LIRE L'ONGLET LOTS
A15: Une ligne = un lot. La colonne statut est coloree : vert = disponible, jaune = optionne,
A16: orange = reserve, gris = vendu, rouge = bloque (logement temoin, hors commercialisation).
... A22: typologie, chiffre d'affaires signe et restant. C'est le tableau de bord du chef de vente.

Sheet Lots
A1: projet | B1: immeuble | C1: niveau | D1: numero_lot | E1: typologie | F1: surface_habitable | G1: surface_balcon | H1: surface_totale | I1: nb_chambres | J1: nb_sdb | K1: orientation | L1: exposition | M1: ascenseur | N1: parking | O1: prix_dh | P1: prix_m2 | Q1: statut | R1: date_fin_option | S1: plan_fichier | T1: notes
A2: jawhara | B2: A | C2: RDC | D2: A-RDC-01 | E2: Commerce | F2: 46 | G2: 0 | H2: =F2+G2 | I2: 0 | J2: 1 | K2: Angle | L2: Sud-Ouest | M2: Oui | N2: Aucun | O2: 694000 | P2: =IFERROR(O2/F2,"") | Q2: Disponible | T2: Local commercial avec vitrine sur la voie principale
A3: jawhara | B3: A | C3: RDC | D3: A-RDC-02 | E3: Commerce | F3: 46 | G3: 0 | H3: =F3+G3 | I3: 0 | J3: 1 | K3: Rue | L3: Sud-Ouest | M3: Oui | N3: Aucun | O3: 687000 | P3: =IFERROR(O3/F3,"") | Q3: Optionne | R3: 2026-08-14 | T3: Local commercial avec vitrine sur la voie principale
A4: jawhara | B4: A | C4: RDC | D4: A-RDC-03 | E4: Bureau | F4: 52 | G4: 0 | H4: =F4+G4 | I4: 0 | J4: 1 | K4: Rue | L4: Sud | M4: Oui | N4: Aucun | O4: 643000 | P4: =IFERROR(O4/F4,"") | Q4: Vendu | T4: Plateau de bureau modulable, entree independante
A5: jawhara | B5: A | C5: RDC | D5: A-RDC-04 | E5: F2 | F5: 61.5 | G5: 7 | H5: =F5+G5 | I5: 1 | J5: 1 | K5: Jardin | L5: Nord-Est | M5: Oui | N5: Exterieur | O5: 590000 | P5: =IFERROR(O5/F5,"") | Q5: Disponible | S5: images/projects/jawhara/plans/f2.png | T5: Acces direct au jardin interieur, ideal pour une famille
A6: jawhara | B6: A | C6: RDC | D6: A-RDC-05 | E6: F3 | F6: 85.5 | G6: 9.5 | H6: =F6+G6 | I6: 2 | J6: 2 | K6: Jardin | L6: Nord-Est | M6: Oui | N6: Exterieur | O6: 794000 | P6: =IFERROR(O6/F6,"") | Q6: Reserve | S6: images/projects/jawhara/plans/f3.png | T6: Acces direct au jardin interieur, ideal pour une famille
A7: jawhara | B7: A | C7: RDC | D7: A-RDC-06 | E7: F2 | F7: 61.5 | G7: 7 | H7: =F7+G7 | I7: 1 | J7: 1 | K7: Cour | L7: Nord | M7: Oui | N7: Exterieur | O7: 578000 | P7: =IFERROR(O7/F7,"") | Q7: Vendu | S7: images/projects/jawhara/plans/f2.png
A8: jawhara | B8: A | C8: 1 | D8: A-1-01 | E8: F3 | F8: 84 | G8: 9.5 | H8: =F8+G8 | I8: 2 | J8: 2 | K8: Rue | L8: Sud-Ouest | M8: Oui | N8: Sous-sol | O8: 803000 | P8: =IFERROR(O8/F8,"") | Q8: Vendu | S8: images/projects/jawhara/plans/f3.png
A9: jawhara | B9: A | C9: 1 | D9: A-1-02 | E9: F2 | F9: 61.5 | G9: 7 | H9: =F9+G9 | I9: 1 | J9: 1 | K9: Rue | L9: Sud-Ouest | M9: Oui | N9: Sous-sol | O9: 607000 | P9: =IFERROR(O9/F9,"") | Q9: Disponible | S9: images/projects/jawhara/plans/f2.png
A10: jawhara | B10: A | C10: 1 | D10: A-1-03 | E10: Studio | F10: 34.5 | G10: 4 | H10: =F10+G10 | I10: 0 | J10: 1 | K10: Cour | L10: Nord | M10: Oui | N10: Sous-sol | O10: 345000 | P10: =IFERROR(O10/F10,"") | Q10: Vendu | S10: images/projects/jawhara/plans/studio.png
A11: jawhara | B11: A | C11: 1 | D11: A-1-04 | E11: F3 | F11: 84 | G11: 9.5 | H11: =F11+G11 | I11: 2 | J11: 2 | K11: Cour | L11: Nord-Est | M11: Oui | N11: Sous-sol | O11: 780000 | P11: =IFERROR(O11/F11,"") | Q11: Vendu | S11: images/projects/jawhara/plans/f3.png
A12: jawhara | B12: A | C12: 1 | D12: A-1-05 | E12: F4 | F12: 109.5 | G12: 12 | H12: =F12+G12 | I12: 3 | J12: 2 | K12: Double orientation | L12: Est | M12: Oui | N12: Sous-sol | O12: 1044000 | P12: =IFERROR(O12/F12,"") | Q12: Reserve | S12: images/projects/jawhara/plans/f4.png | T12: Traversant : lumiere du matin et du soir
A13: jawhara | B13: A | C13: 1 | D13: A-1-06 | E13: F2 | F13: 61.5 | G13: 7 | H13: =F13+G13 | I13: 1 | J13: 1 | K13: Angle | L13: Nord-Ouest | M13: Oui | N13: Sous-sol | O13: 613000 | P13: =IFERROR(O13/F13,"") | Q13: Vendu | S13: images/projects/jawhara/plans/f2.png | T13: Appartement d'angle, deux facades
A14: jawhara | B14: A | C14: 2 | D14: A-2-01 | E14: F3 | F14: 84 | G14: 9.5 | H14: =F14+G14 | I14: 2 | J14: 2 | K14: Rue | L14: Sud-Ouest | M14: Oui | N14: Sous-sol | O14: 819000 | P14: =IFERROR(O14/F14,"") | Q14: Reserve | S14: images/projects/jawhara/plans/f3.png
A15: jawhara | B15: A | C15: 2 | D15: A-2-02 | E15: F2 | F15: 61.5 | G15: 7 | H15: =F15+G15 | I15: 1 | J15: 1 | K15: Rue | L15: Sud-Ouest | M15: Oui | N15: Sous-sol | O15: 619000 | P15: =IFERROR(O15/F15,"") | Q15: Disponible | S15: images/projects/jawhara/plans/f2.png
A16: jawhara | B16: A | C16: 2 | D16: A-2-03 | E16: Studio | F16: 34.5 | G16: 4 | H16: =F16+G16 | I16: 0 | J16: 1 | K16: Cour | L16: Nord | M16: Oui | N16: Sous-sol | O16: 352000 | P16: =IFERROR(O16/F16,"") | Q16: Bloque | S16: images/projects/jawhara/plans/studio.png | T16: Logement temoin, non commercialise
A17: jawhara | B17: A | C17: 2 | D17: A-2-04 | E17: F3 | F17: 84 | G17: 9.5 | H17: =F17+G17 | I17: 2 | J17: 2 | K17: Cour | L17: Nord-Est | M17: Oui | N17: Sous-sol | O17: 795000 | P17: =IFERROR(O17/F17,"") | Q17: Reserve | S17: images/projects/jawhara/plans/f3.png
A18: jawhara | B18: A | C18: 2 | D18: A-2-05 | E18: F4 | F18: 109.5 | G18: 12 | H18: =F18+G18 | I18: 3 | J18: 2 | K18: Double orientation | L18: Est | M18: Oui | N18: Sous-sol | O18: 1064000 | P18: =IFERROR(O18/F18,"") | Q18: Disponible | S18: images/projects/jawhara/plans/f4.png | T18: Traversant : lumiere du matin et du soir
A19: jawhara | B19: A | C19: 2 | D19: A-2-06 | E19: F2 | F19: 61.5 | G19: 7 | H19: =F19+G19 | I19: 1 | J19: 1 | K19: Angle | L19: Nord-Ouest | M19: Oui | N19: Sous-sol | O19: 625000 | P19: =IFERROR(O19/F19,"") | Q19: Disponible | S19: images/projects/jawhara/plans/f2.png | T19: Appartement d'angle, deux facades
A20: jawhara | B20: A | C20: 3 | D20: A-3-01 | E20: F3 | F20: 84 | G20: 9.5 | H20: =F20+G20 | I20: 2 | J20: 2 | K20: Rue | L20: Sud-Ouest | M20: Oui | N20: Sous-sol | O20: 835000 | P20: =IFERROR(O20/F20,"") | Q20: Disponible | S20: images/projects/jawhara/plans/f3.png
A21: jawhara | B21: A | C21: 3 | D21: A-3-02 | E21: F2 | F21: 61.5 | G21: 7 | H21: =F21+G21 | I21: 1 | J21: 1 | K21: Rue | L21: Sud-Ouest | M21: Oui | N21: Sous-sol | O21: 631000 | P21: =IFERROR(O21/F21,"") | Q21: Vendu | S21: images/projects/jawhara/plans/f2.png
A22: jawhara | B22: A | C22: 3 | D22: A-3-03 | E22: Studio | F22: 34.5 | G22: 4 | H22: =F22+G22 | I22: 0 | J22: 1 | K22: Cour | L22: Nord | M22: Oui | N22: Sous-sol | O22: 358000 | P22: =IFERROR(O22/F22,"") | Q22: Disponible | S22: images/projects/jawhara/plans/studio.png
A23: jawhara | B23: A | C23: 3 | D23: A-3-04 | E23: F3 | F23: 84 | G23: 9.5 | H23: =F23+G23 | I23: 2 | J23: 2 | K23: Cour | L23: Nord-Est | M23: Oui | N23: Sous-sol | O23: 810000 | P23: =IFERROR(O23/F23,"") | Q23: Vendu | S23: images/projects/jawhara/plans/f3.png
A24: jawhara | B24: A | C24: 3 | D24: A-3-05 | E24: F4 | F24: 109.5 | G24: 12 | H24: =F24+G24 | I24: 3 | J24: 2 | K24: Double orientation | L24: Est | M24: Oui | N24: Sous-sol | O24: 1085000 | P24: =IFERROR(O24/F24,"") | Q24: Vendu | S24: images/projects/jawhara/plans/f4.png | T24: Traversant : lumiere du matin et du soir
A25: jawhara | B25: A | C25: 3 | D25: A-3-06 | E25: F2 | F25: 61.5 | G25: 7 | H25: =F25+G25 | I25: 1 | J25: 1 | K25: Angle | L25: Nord-Ouest | M25: Oui | N25: Sous-sol | O25: 637000 | P25: =IFERROR(O25/F25,"") | Q25: Disponible | S25: images/projects/jawhara/plans/f2.png | T25: Appartement d'angle, deux facades
A26: jawhara | B26: A | C26: 4 | D26: A-4-01 | E26: Duplex | F26: 132 | G26: 24 | H26: =F26+G26 | I26: 4 | J26: 3 | K26: Rue | L26: Sud-Ouest | M26: Oui | N26: Sous-sol | O26: 1423000 | P26: =IFERROR(O26/F26,"") | Q26: Vendu | S26: images/projects/jawhara/plans/duplex.png | T26: Duplex avec terrasse privative, vue degagee sur l'Atlas
A27: jawhara | B27: A | C27: 4 | D27: A-4-02 | E27: F4 | F27: 108 | G27: 12 | H27: =F27+G27 | I27: 3 | J27: 2 | K27: Rue | L27: Sud-Ouest | M27: Oui | N27: Sous-sol | O27: 1079000 | P27: =IFERROR(O27/F27,"") | Q27: Reserve | S27: images/projects/jawhara/plans/f4.png | T27: Dernier etage, terrasse privative
A28: jawhara | B28: A | C28: 4 | D28: A-4-03 | E28: F2 | F28: 61.5 | G28: 7 | H28: =F28+G28 | I28: 1 | J28: 1 | K28: Cour | L28: Nord | M28: Oui | N28: Sous-sol | O28: 630000 | P28: =IFERROR(O28/F28,"") | Q28: Reserve | S28: images/projects/jawhara/plans/f2.png | T28: Dernier etage, terrasse privative
A29: jawhara | B29: A | C29: 4 | D29: A-4-04 | E29: F3 | F29: 84 | G29: 9.5 | H29: =F29+G29 | I29: 2 | J29: 2 | K29: Cour | L29: Nord-Est | M29: Oui | N29: Sous-sol | O29: 833000 | P29: =IFERROR(O29/F29,"") | Q29: Vendu | S29: images/projects/jawhara/plans/f3.png | T29: Dernier etage, terrasse privative
A30: jawhara | B30: A | C30: 4 | D30: A-4-05 | E30: Duplex | F30: 133.5 | G30: 24 | H30: =F30+G30 | I30: 4 | J30: 3 | K30: Double orientation | L30: Est | M30: Oui | N30: Sous-sol | O30: 1467000 | P30: =IFERROR(O30/F30,"") | Q30: Disponible | S30: images/projects/jawhara/plans/duplex.png | T30: Duplex avec terrasse privative, vue degagee sur l'Atlas
A31: jawhara | B31: A | C31: 4 | D31: A-4-06 | E31: F3 | F31: 84 | G31: 9.5 | H31: =F31+G31 | I31: 2 | J31: 2 | K31: Angle | L31: Nord-Ouest | M31: Oui | N31: Sous-sol | O31: 867000 | P31: =IFERROR(O31/F31,"") | Q31: Optionne | R31: 2026-08-09 | S31: images/projects/jawhara/plans/f3.png | T31: Dernier etage, terrasse privative
A32: jawhara | B32: B | C32: RDC | D32: B-RDC-01 | E32: Commerce | F32: 46.5 | G32: 0 | H32: =F32+G32 | I32: 0 | J32: 1 | K32: Angle | L32: Sud-Ouest | M32: Oui | N32: Aucun | O32: 708000 | P32: =IFERROR(O32/F32,"") | Q32: Disponible | T32: Local commercial avec vitrine sur la voie principale
A33: jawhara | B33: B | C33: RDC | D33: B-RDC-02 | E33: Commerce | F33: 46.5 | G33: 0 | H33: =F33+G33 | I33: 0 | J33: 1 | K33: Rue | L33: Sud-Ouest | M33: Oui | N33: Aucun | O33: 701000 | P33: =IFERROR(O33/F33,"") | Q33: Disponible | T33: Local commercial avec vitrine sur la voie principale
A34: jawhara | B34: B | C34: RDC | D34: B-RDC-03 | E34: Bureau | F34: 52.5 | G34: 0 | H34: =F34+G34 | I34: 0 | J34: 1 | K34: Rue | L34: Sud | M34: Oui | N34: Aucun | O34: 655000 | P34: =IFERROR(O34/F34,"") | Q34: Disponible | T34: Plateau de bureau modulable, entree independante
A35: jawhara | B35: B | C35: RDC | D35: B-RDC-04 | E35: F2 | F35: 62 | G35: 7 | H35: =F35+G35 | I35: 1 | J35: 1 | K35: Jardin | L35: Nord-Est | M35: Oui | N35: Exterieur | O35: 600000 | P35: =IFERROR(O35/F35,"") | Q35: Vendu | S35: images/projects/jawhara/plans/f2.png | T35: Acces direct au jardin interieur, ideal pour une famille
A36: jawhara | B36: B | C36: RDC | D36: B-RDC-05 | E36: F3 | F36: 86 | G36: 9.5 | H36: =F36+G36 | I36: 2 | J36: 2 | K36: Jardin | L36: Nord-Est | M36: Oui | N36: Exterieur | O36: 806000 | P36: =IFERROR(O36/F36,"") | Q36: Disponible | S36: images/projects/jawhara/plans/f3.png | T36: Acces direct au jardin interieur, ideal pour une famille
A37: jawhara | B37: B | C37: RDC | D37: B-RDC-06 | E37: F2 | F37: 62 | G37: 7 | H37: =F37+G37 | I37: 1 | J37: 1 | K37: Cour | L37: Nord | M37: Oui | N37: Exterieur | O37: 589000 | P37: =IFERROR(O37/F37,"") | Q37: Disponible | S37: images/projects/jawhara/plans/f2.png
A38: jawhara | B38: B | C38: 1 | D38: B-1-01 | E38: F3 | F38: 84.5 | G38: 9.5 | H38: =F38+G38 | I38: 2 | J38: 2 | K38: Rue | L38: Sud-Ouest | M38: Oui | N38: Sous-sol | O38: 816000 | P38: =IFERROR(O38/F38,"") | Q38: Disponible | S38: images/projects/jawhara/plans/f3.png
A39: jawhara | B39: B | C39: 1 | D39: B-1-02 | E39: F2 | F39: 62 | G39: 7 | H39: =F39+G39 | I39: 1 | J39: 1 | K39: Rue | L39: Sud-Ouest | M39: Oui | N39: Sous-sol | O39: 618000 | P39: =IFERROR(O39/F39,"") | Q39: Optionne | R39: 2026-08-14 | S39: images/projects/jawhara/plans/f2.png
A40: jawhara | B40: B | C40: 1 | D40: B-1-03 | E40: Studio | F40: 35 | G40: 4 | H40: =F40+G40 | I40: 0 | J40: 1 | K40: Cour | L40: Nord | M40: Oui | N40: Sous-sol | O40: 353000 | P40: =IFERROR(O40/F40,"") | Q40: Disponible | S40: images/projects/jawhara/plans/studio.png
...

Sheet Synthese
A1: Etat de la commercialisation
A2: Se recalcule automatiquement depuis l'onglet Lots.
A4: Par immeuble
B5: Disponible | C5: Optionne | D5: Reserve | E5: Vendu | F5: Bloque | G5: Total
A6: A | B6: =COUNTIFS(Lots!$B$2:$B$91,"A",Lots!$Q$2:$Q$91,"Disponible") | C6: =COUNTIFS(Lots!$B$2:$B$91,"A",Lots!$Q$2:$Q$91,"Optionne") | D6: =COUNTIFS(Lots!$B$2:$B$91,"A",Lots!$Q$2:$Q$91,"Reserve") | E6: =COUNTIFS(Lots!$B$2:$B$91,"A",Lots!$Q$2:$Q$91,"Vendu") | F6: =COUNTIFS(Lots!$B$2:$B$91,"A",Lots!$Q$2:$Q$91,"Bloque") | G6: =SUM(B6:F6)
A7: B | B7: =COUNTIFS(Lots!$B$2:$B$91,"B",Lots!$Q$2:$Q$91,"Disponible") | C7: =COUNTIFS(Lots!$B$2:$B$91,"B",Lots!$Q$2:$Q$91,"Optionne") | D7: =COUNTIFS(Lots!$B$2:$B$91,"B",Lots!$Q$2:$Q$91,"Reserve") | E7: =COUNTIFS(Lots!$B$2:$B$91,"B",Lots!$Q$2:$Q$91,"Vendu") | F7: =COUNTIFS(Lots!$B$2:$B$91,"B",Lots!$Q$2:$Q$91,"Bloque") | G7: =SUM(B7:F7)
A8: C | B8: =COUNTIFS(Lots!$B$2:$B$91,"C",Lots!$Q$2:$Q$91,"Disponible") | C8: =COUNTIFS(Lots!$B$2:$B$91,"C",Lots!$Q$2:$Q$91,"Optionne") | D8: =COUNTIFS(Lots!$B$2:$B$91,"C",Lots!$Q$2:$Q$91,"Reserve") | E8: =COUNTIFS(Lots!$B$2:$B$91,"C",Lots!$Q$2:$Q$91,"Vendu") | F8: =COUNTIFS(Lots!$B$2:$B$91,"C",Lots!$Q$2:$Q$91,"Bloque") | G8: =SUM(B8:F8)
A10: Par typologie
B11: Disponible | C11: Optionne | D11: Reserve | E11: Vendu | F11: Bloque | G11: Total
A12: Studio | B12: =COUNTIFS(Lots!$E$2:$E$91,"Studio",Lots!$Q$2:$Q$91,"Disponible") | C12: =COUNTIFS(Lots!$E$2:$E$91,"Studio",Lots!$Q$2:$Q$91,"Optionne") | D12: =COUNTIFS(Lots!$E$2:$E$91,"Studio",Lots!$Q$2:$Q$91,"Reserve") | E12: =COUNTIFS(Lots!$E$2:$E$91,"Studio",Lots!$Q$2:$Q$91,"Vendu") | F12: =COUNTIFS(Lots!$E$2:$E$91,"Studio",Lots!$Q$2:$Q$91,"Bloque") | G12: =SUM(B12:F12)
A13: F2 | B13: =COUNTIFS(Lots!$E$2:$E$91,"F2",Lots!$Q$2:$Q$91,"Disponible") | C13: =COUNTIFS(Lots!$E$2:$E$91,"F2",Lots!$Q$2:$Q$91,"Optionne") | D13: =COUNTIFS(Lots!$E$2:$E$91,"F2",Lots!$Q$2:$Q$91,"Reserve") | E13: =COUNTIFS(Lots!$E$2:$E$91,"F2",Lots!$Q$2:$Q$91,"Vendu") | F13: =COUNTIFS(Lots!$E$2:$E$91,"F2",Lots!$Q$2:$Q$91,"Bloque") | G13: =SUM(B13:F13)
A14: F3 | B14: =COUNTIFS(Lots!$E$2:$E$91,"F3",Lots!$Q$2:$Q$91,"Disponible") | C14: =COUNTIFS(Lots!$E$2:$E$91,"F3",Lots!$Q$2:$Q$91,"Optionne") | D14: =COUNTIFS(Lots!$E$2:$E$91,"F3",Lots!$Q$2:$Q$91,"Reserve") | E14: =COUNTIFS(Lots!$E$2:$E$91,"F3",Lots!$Q$2:$Q$91,"Vendu") | F14: =COUNTIFS(Lots!$E$2:$E$91,"F3",Lots!$Q$2:$Q$91,"Bloque") | G14: =SUM(B14:F14)
A15: F4 | B15: =COUNTIFS(Lots!$E$2:$E$91,"F4",Lots!$Q$2:$Q$91,"Disponible") | C15: =COUNTIFS(Lots!$E$2:$E$91,"F4",Lots!$Q$2:$Q$91,"Optionne") | D15: =COUNTIFS(Lots!$E$2:$E$91,"F4",Lots!$Q$2:$Q$91,"Reserve") | E15: =COUNTIFS(Lots!$E$2:$E$91,"F4",Lots!$Q$2:$Q$91,"Vendu") | F15: =COUNTIFS(Lots!$E$2:$E$91,"F4",Lots!$Q$2:$Q$91,"Bloque") | G15: =SUM(B15:F15)
A16: Duplex | B16: =COUNTIFS(Lots!$E$2:$E$91,"Duplex",Lots!$Q$2:$Q$91,"Disponible") | C16: =COUNTIFS(Lots!$E$2:$E$91,"Duplex",Lots!$Q$2:$Q$91,"Optionne") | D16: =COUNTIFS(Lots!$E$2:$E$91,"Duplex",Lots!$Q$2:$Q$91,"Reserve") | E16: =COUNTIFS(Lots!$E$2:$E$91,"Duplex",Lots!$Q$2:$Q$91,"Vendu") | F16: =COUNTIFS(Lots!$E$2:$E$91,"Duplex",Lots!$Q$2:$Q$91,"Bloque") | G16: =SUM(B16:F16)
A17: Bureau | B17: =COUNTIFS(Lots!$E$2:$E$91,"Bureau",Lots!$Q$2:$Q$91,"Disponible") | C17: =COUNTIFS(Lots!$E$2:$E$91,"Bureau",Lots!$Q$2:$Q$91,"Optionne") | D17: =COUNTIFS(Lots!$E$2:$E$91,"Bureau",Lots!$Q$2:$Q$91,"Reserve") | E17: =COUNTIFS(Lots!$E$2:$E$91,"Bureau",Lots!$Q$2:$Q$91,"Vendu") | F17: =COUNTIFS(Lots!$E$2:$E$91,"Bureau",Lots!$Q$2:$Q$91,"Bloque") | G17: =SUM(B17:F17)
A18: Commerce | B18: =COUNTIFS(Lots!$E$2:$E$91,"Commerce",Lots!$Q$2:$Q$91,"Disponible") | C18: =COUNTIFS(Lots!$E$2:$E$91,"Commerce",Lots!$Q$2:$Q$91,"Optionne") | D18: =COUNTIFS(Lots!$E$2:$E$91,"Commerce",Lots!$Q$2:$Q$91,"Reserve") | E18: =COUNTIFS(Lots!$E$2:$E$91,"Commerce",Lots!$Q$2:$Q$91,"Vendu") | F18: =COUNTIFS(Lots!$E$2:$E$91,"Commerce",Lots!$Q$2:$Q$91,"Bloque") | G18: =SUM(B18:F18)
A20: Par orientation
B21: Disponible | C21: Optionne | D21: Reserve | E21: Vendu | F21: Bloque | G21: Total
A22: Rue | B22: =COUNTIFS(Lots!$K$2:$K$91,"Rue",Lots!$Q$2:$Q$91,"Disponible") | C22: =COUNTIFS(Lots!$K$2:$K$91,"Rue",Lots!$Q$2:$Q$91,"Optionne") | D22: =COUNTIFS(Lots!$K$2:$K$91,"Rue",Lots!$Q$2:$Q$91,"Reserve") | E22: =COUNTIFS(Lots!$K$2:$K$91,"Rue",Lots!$Q$2:$Q$91,"Vendu") | F22: =COUNTIFS(Lots!$K$2:$K$91,"Rue",Lots!$Q$2:$Q$91,"Bloque") | G22: =SUM(B22:F22)
A23: Cour | B23: =COUNTIFS(Lots!$K$2:$K$91,"Cour",Lots!$Q$2:$Q$91,"Disponible") | C23: =COUNTIFS(Lots!$K$2:$K$91,"Cour",Lots!$Q$2:$Q$91,"Optionne") | D23: =COUNTIFS(Lots!$K$2:$K$91,"Cour",Lots!$Q$2:$Q$91,"Reserve") | E23: =COUNTIFS(Lots!$K$2:$K$91,"Cour",Lots!$Q$2:$Q$91,"Vendu") | F23: =COUNTIFS(Lots!$K$2:$K$91,"Cour",Lots!$Q$2:$Q$91,"Bloque") | G23: =SUM(B23:F23)
A24: Jardin | B24: =COUNTIFS(Lots!$K$2:$K$91,"Jardin",Lots!$Q$2:$Q$91,"Disponible") | C24: =COUNTIFS(Lots!$K$2:$K$91,"Jardin",Lots!$Q$2:$Q$91,"Optionne") | D24: =COUNTIFS(Lots!$K$2:$K$91,"Jardin",Lots!$Q$2:$Q$91,"Reserve") | E24: =COUNTIFS(Lots!$K$2:$K$91,"Jardin",Lots!$Q$2:$Q$91,"Vendu") | F24: =COUNTIFS(Lots!$K$2:$K$91,"Jardin",Lots!$Q$2:$Q$91,"Bloque") | G24: =SUM(B24:F24)
A25: Double orientation | B25: =COUNTIFS(Lots!$K$2:$K$91,"Double orientation",Lots!$Q$2:$Q$91,"Disponible") | C25: =COUNTIFS(Lots!$K$2:$K$91,"Double orientation",Lots!$Q$2:$Q$91,"Optionne") | D25: =COUNTIFS(Lots!$K$2:$K$91,"Double orientation",Lots!$Q$2:$Q$91,"Reserve") | E25: =COUNTIFS(Lots!$K$2:$K$91,"Double orientation",Lots!$Q$2:$Q$91,"Vendu") | F25: =COUNTIFS(Lots!$K$2:$K$91,"Double orientation",Lots!$Q$2:$Q$91,"Bloque") | G25: =SUM(B25:F25)
A26: Angle | B26: =COUNTIFS(Lots!$K$2:$K$91,"Angle",Lots!$Q$2:$Q$91,"Disponible") | C26: =COUNTIFS(Lots!$K$2:$K$91,"Angle",Lots!$Q$2:$Q$91,"Optionne") | D26: =COUNTIFS(Lots!$K$2:$K$91,"Angle",Lots!$Q$2:$Q$91,"Reserve") | E26: =COUNTIFS(Lots!$K$2:$K$91,"Angle",Lots!$Q$2:$Q$91,"Vendu") | F26: =COUNTIFS(Lots!$K$2:$K$91,"Angle",Lots!$Q$2:$Q$91,"Bloque") | G26: =SUM(B26:F26)
A28: Chiffre d'affaires
A29: Total du programme | B29: =SUM(Lots!$O$2:$O$91)
A30: Signe (vendu) | B30: =SUMIFS(Lots!$O$2:$O$91,Lots!$Q$2:$Q$91,"Vendu")
A31: Engage (reserve + optionne) | B31: =SUMIFS(Lots!$O$2:$O$91,Lots!$Q$2:$Q$91,"Reserve")+SUMIFS(Lots!$O$2:$O$91,Lots!$Q$2:$Q$91,"Optionne")
A32: Restant a vendre | B32: =SUMIFS(Lots!$O$2:$O$91,Lots!$Q$2:$Q$91,"Disponible")
A33: Prix moyen au m2 | B33: =IFERROR(SUM(Lots!$O$2:$O$91)/SUM(Lots!$F$2:$F$91),"")
A34: Surface totale (m2) | B34: =SUM(Lots!$F$2:$F$91)

Sheet Listes
A1: Valeurs autorisees dans les listes deroulantes de l'onglet Lots
A3: typologie | B3: orientation | C3: exposition | D3: statut | E3: ascenseur | F3: parking | G3: niveau | H3: immeuble
A4: Studio | B4: Rue | C4: Nord | D4: Disponible | E4: Oui | F4: Aucun | G4: RDC | H4: A
A5: F2 | B5: Cour | C5: Nord-Est | D5: Optionne | E5: Non | F5: Sous-sol | G5: 1 | H5: B
A6: F3 | B6: Jardin | C6: Est | D6: Reserve | F6: Exterieur | G6: 2 | H6: C
A7: F4 | B7: Double orientation | C7: Sud-Est | D7: Vendu | F7: Box | G7: 3
A8: F5 | B8: Angle | C8: Sud | D8: Bloque | G8: 4
A9: Duplex | C9: Sud-Ouest
A10: Bureau | C10: Ouest
A11: Commerce | C11: Nord-Ouest
